<?xml version="1.0" ?>
<!-- =================================================================================== -->
<!-- |    This document was autogenerated by xacro from urdf/nova_right.xacro          | -->
<!-- |    EDITING THIS FILE BY HAND IS NOT RECOMMENDED                                 | -->
<!-- =================================================================================== -->
<!-- Revolute-Revolute Manipulator -->
<robot name="nova">
  <!-- Cube dimensions (width x width x width) of joint base -->
  <!-- rad/s -->
  <!-- Used for fixing robot to Gazebo 'world' -->
  <link name="world"/>
  <!-- glove hub -->
  <link name="r_glove_hub">
    <visual>
      <origin rpy="0 0 0" xyz="-0.056692 -0.01955 -0.06803"/>
      <geometry>
        <mesh filename="package://senseglove_description/urdf/STL/MK29_DK1_HUB.STL" scale="0.001 0.001 0.001"/>
      </geometry>
    </visual>
  </link>
  <!-- thumb brake -->
  <link name="r_thumb_brake">
    <visual>
      <origin rpy="0 0 0" xyz="-0.0111395 -0.01815 -0.11359999999999999"/>
      <geometry>
        <mesh filename="package://senseglove_description/urdf/STL/MK29_DK1_Brake_assembly_v2.STL" scale="0.001 0.001 0.001"/>
      </geometry>
    </visual>
  </link>
  <!-- thumb abduction -->
  <link name="r_thumb_abduction">
    <visual>
      <origin rpy="0 0 0" xyz="-0.0111395 -0.025300000000000003 -0.1166"/>
      <geometry>
        <mesh filename="package://senseglove_description/urdf/STL/MK29_DK1_Abduction_joint_v2.STL" scale="0.001 0.001 0.001"/>
      </geometry>
    </visual>
  </link>
  <!-- thumb flexion one -->
  <link name="r_thumb_flexion_one">
    <visual>
      <origin rpy="0 0 0" xyz="-0.0111395 -0.0263 -0.0931"/>
      <geometry>
        <mesh filename="package://senseglove_description/urdf/STL/MK29_DK1_Flexion_joint_1_v2.STL" scale="0.001 0.001 0.001"/>
      </geometry>
    </visual>
  </link>
  <!-- thumb flexion two -->
  <link name="r_thumb_flexion_two">
    <visual>
      <origin rpy="0 0 0" xyz="-0.0111395 -0.0263 -0.092955"/>
      <geometry>
        <mesh filename="package://senseglove_description/urdf/STL/MK29_DK1_Flexion_joint_2_v2.STL" scale="0.001 0.001 0.001"/>
      </geometry>
    </visual>
  </link>
  <!-- thumb flexion three -->
  <link name="r_thumb_flexion_three">
    </link>
  <!-- index brake -->
  <link name="r_index_brake">
    <visual>
      <origin rpy="0 0 0" xyz="-0.0111395 -0.01815 -0.11359999999999999"/>
      <geometry>
        <mesh filename="package://senseglove_description/urdf/STL/MK29_DK1_Brake_assembly_v2.STL" scale="0.001 0.001 0.001"/>
      </geometry>
    </visual>
  </link>
  <!-- index abduction -->
  <link name="r_index_abduction">
    <visual>
      <origin rpy="0 0 0" xyz="-0.0111395 -0.025300000000000003 -0.1166"/>
      <geometry>
        <mesh filename="package://senseglove_description/urdf/STL/MK29_DK1_Abduction_joint_v2.STL" scale="0.001 0.001 0.001"/>
      </geometry>
    </visual>
  </link>
  <!-- index flexion one -->
  <link name="r_index_flexion_one">
    <visual>
      <origin rpy="0 0 0" xyz="-0.0111395 -0.0263 -0.0931"/>
      <geometry>
        <mesh filename="package://senseglove_description/urdf/STL/MK29_DK1_Flexion_joint_1_v2.STL" scale="0.001 0.001 0.001"/>
      </geometry>
    </visual>
  </link>
  <!-- index flexion two -->
  <link name="r_index_flexion_two">
    <visual>
      <origin rpy="0 0 0" xyz="-0.0111395 -0.0263 -0.092955"/>
      <geometry>
        <mesh filename="package://senseglove_description/urdf/STL/MK29_DK1_Flexion_joint_2_v2.STL" scale="0.001 0.001 0.001"/>
      </geometry>
    </visual>
  </link>
  <!-- index flexion three -->
  <link name="r_index_flexion_three">
    </link>
  <!-- middle brake -->
  <link name="r_middle_brake">
    <visual>
      <origin rpy="0 0 0" xyz="-0.0111395 -0.01815 -0.11359999999999999"/>
      <geometry>
        <mesh filename="package://senseglove_description/urdf/STL/MK29_DK1_Brake_assembly_v2.STL" scale="0.001 0.001 0.001"/>
      </geometry>
    </visual>
  </link>
  <!-- middle abduction -->
  <link name="r_middle_abduction">
    <visual>
      <origin rpy="0 0 0" xyz="-0.0111395 -0.025300000000000003 -0.1166"/>
      <geometry>
        <mesh filename="package://senseglove_description/urdf/STL/MK29_DK1_Abduction_joint_v2.STL" scale="0.001 0.001 0.001"/>
      </geometry>
    </visual>
  </link>
  <!-- middle flexion one -->
  <link name="r_middle_flexion_one">
    <visual>
      <origin rpy="0 0 0" xyz="-0.0111395 -0.0263 -0.0931"/>
      <geometry>
        <mesh filename="package://senseglove_description/urdf/STL/MK29_DK1_Flexion_joint_1_v2.STL" scale="0.001 0.001 0.001"/>
      </geometry>
    </visual>
  </link>
  <!-- middle flexion two -->
  <link name="r_middle_flexion_two">
    <visual>
      <origin rpy="0 0 0" xyz="-0.0111395 -0.0263 -0.092955"/>
      <geometry>
        <mesh filename="package://senseglove_description/urdf/STL/MK29_DK1_Flexion_joint_2_v2.STL" scale="0.001 0.001 0.001"/>
      </geometry>
    </visual>
  </link>
  <!-- middle flexion three -->
  <link name="r_middle_flexion_three">
    </link>
  <!-- ring brake -->
  <link name="r_ring_brake">
    <visual>
      <origin rpy="0 0 0" xyz="-0.0111395 -0.01815 -0.11359999999999999"/>
      <geometry>
        <mesh filename="package://senseglove_description/urdf/STL/MK29_DK1_Brake_assembly_v2.STL" scale="0.001 0.001 0.001"/>
      </geometry>
    </visual>
  </link>
  <!-- ring abduction -->
  <link name="r_ring_abduction">
    <visual>
      <origin rpy="0 0 0" xyz="-0.0111395 -0.025300000000000003 -0.1166"/>
      <geometry>
        <mesh filename="package://senseglove_description/urdf/STL/MK29_DK1_Abduction_joint_v2.STL" scale="0.001 0.001 0.001"/>
      </geometry>
    </visual>
  </link>
  <!-- ring flexion one -->
  <link name="r_ring_flexion_one">
    <visual>
      <origin rpy="0 0 0" xyz="-0.0111395 -0.0263 -0.0931"/>
      <geometry>
        <mesh filename="package://senseglove_description/urdf/STL/MK29_DK1_Flexion_joint_1_v2.STL" scale="0.001 0.001 0.001"/>
      </geometry>
    </visual>
  </link>
  <!-- ring flexion two -->
  <link name="r_ring_flexion_two">
    <visual>
      <origin rpy="0 0 0" xyz="-0.0111395 -0.0263 -0.092955"/>
      <geometry>
        <mesh filename="package://senseglove_description/urdf/STL/MK29_DK1_Flexion_joint_2_v2.STL" scale="0.001 0.001 0.001"/>
      </geometry>
    </visual>
  </link>
  <!-- ring flexion three -->
  <link name="r_ring_flexion_three">
    </link>
  <!-- pinky brake -->
  <link name="r_pinky_brake">
    <visual>
      <origin rpy="0 0 0" xyz="-0.0115395 -0.01815 -0.1166"/>
      <geometry>
        <mesh filename="package://senseglove_description/urdf/STL/MK29_DK1_Brake_assembly_v2.STL" scale="0.001 0.001 0.001"/>
      </geometry>
    </visual>
  </link>
  <!-- pinky abduction -->
  <link name="r_pinky_abduction">
    <visual>
      <origin rpy="0 0 0" xyz="-0.0111395 -0.025300000000000003 -0.1166"/>
      <geometry>
        <mesh filename="package://senseglove_description/urdf/STL/MK29_DK1_Abduction_joint_v2.STL" scale="0.001 0.001 0.001"/>
      </geometry>
    </visual>
  </link>
  <!-- pinky flexion one -->
  <link name="r_pinky_flexion_one">
    <visual>
      <origin rpy="0 0 0" xyz="-0.0111395 -0.0263 -0.0931"/>
      <geometry>
        <mesh filename="package://senseglove_description/urdf/STL/MK29_DK1_Flexion_joint_1_v2.STL" scale="0.001 0.001 0.001"/>
      </geometry>
    </visual>
  </link>
  <!-- pinky flexion two -->
  <link name="r_pinky_flexion_two">
    <visual>
      <origin rpy="0 0 0" xyz="-0.0111395 -0.0263 -0.092955"/>
      <geometry>
        <mesh filename="package://senseglove_description/urdf/STL/MK29_DK1_Flexion_joint_2_v2.STL" scale="0.001 0.001 0.001"/>
      </geometry>
    </visual>
  </link>
  <!-- pinky flexion three -->
  <link name="r_pinky_flexion_three">
    </link>
  <!-- Joints -->
  <joint name="joint_base_fixed_parent_joint" type="fixed">
    <parent link="world"/>
    <child link="r_glove_hub"/>
    <origin rpy="0 0 0" xyz="0.5 0 0.5"/>
  </joint>
  <joint name="r_hub_to_thumb_brake" type="fixed">
    <parent link="r_glove_hub"/>
    <child link="r_thumb_brake"/>
    <origin rpy="1.9460421159736774 0.6981317007977318 2.9670597283903604" xyz="-0.052034 -0.0221293 0.04656"/>
  </joint>
  <joint name="r_thumb_brake" type="revolute">
    <parent link="r_thumb_brake"/>
    <child link="r_thumb_abduction"/>
    <origin rpy="0 0 0" xyz="0 0.0074 -0.0"/>
    <axis xyz="0 1 0"/>
    <limit effort="100" lower="0" upper="100" velocity="1000"/>
  </joint>
  <joint name="r_thumb_abduction" type="fixed">
    <parent link="r_thumb_abduction"/>
    <child link="r_thumb_flexion_one"/>
    <origin rpy="0 0 0" xyz="0 0 -0.02325"/>
  </joint>
  <joint name="r_thumb_mcp" type="revolute">
    <parent link="r_thumb_flexion_one"/>
    <child link="r_thumb_flexion_two"/>
    <origin rpy="0 0 0" xyz="0 0 0"/>
    <axis xyz="-1 0 0"/>
    <limit effort="100" lower="0" upper="100" velocity="1000"/>
  </joint>
  <joint name="r_thumb_tip" type="revolute">
    <parent link="r_thumb_flexion_two"/>
    <child link="r_thumb_flexion_three"/>
    <origin rpy="0 0 0" xyz="0 0 -0.0876"/>
    <axis xyz="-1 0 0"/>
    <limit effort="100" lower="0" upper="100" velocity="1000"/>
  </joint>
  <joint name="r_hub_to_index_brake" type="fixed">
    <parent link="r_glove_hub"/>
    <child link="r_index_brake"/>
    <origin rpy="0 0 0" xyz="-0.03309 0.00645 -0.04436"/>
  </joint>
  <joint name="r_index_brake" type="revolute">
    <parent link="r_index_brake"/>
    <child link="r_index_abduction"/>
    <origin rpy="0 0 0" xyz="0 0.0074 -0.0"/>
    <axis xyz="0 1 0"/>
    <limit effort="100" lower="-2" upper="100" velocity="1000"/>
  </joint>
  <joint name="r_index_abduction" type="fixed">
    <parent link="r_index_abduction"/>
    <child link="r_index_flexion_one"/>
    <origin rpy="0 0 0" xyz="0 0 -0.02325"/>
  </joint>
  <joint name="r_index_mcp" type="revolute">
    <parent link="r_index_flexion_one"/>
    <child link="r_index_flexion_two"/>
    <origin rpy="0 0 0" xyz="0 0 0"/>
    <axis xyz="-1 0 0"/>
    <limit effort="100" lower="-2" upper="100" velocity="1000"/>
  </joint>
  <joint name="r_index_tip" type="revolute">
    <parent link="r_index_flexion_two"/>
    <child link="r_index_flexion_three"/>
    <origin rpy="0 0 0" xyz="0 0 -0.0876"/>
    <axis xyz="-1 0 0"/>
    <limit effort="100" lower="0" upper="100" velocity="1000"/>
  </joint>
  <joint name="r_hub_to_middle_brake" type="fixed">
    <parent link="r_glove_hub"/>
    <child link="r_middle_brake"/>
    <origin rpy="0 0 0" xyz="-0.011 0.008 -0.06222"/>
  </joint>
  <joint name="r_middle_brake" type="revolute">
    <parent link="r_middle_brake"/>
    <child link="r_middle_abduction"/>
    <origin rpy="0 0 0" xyz="0 0.0074 -0.0"/>
    <axis xyz="0 1 0"/>
    <limit effort="100" lower="-2" upper="100" velocity="1000"/>
  </joint>
  <joint name="r_middle_abduction" type="fixed">
    <parent link="r_middle_abduction"/>
    <child link="r_middle_flexion_one"/>
    <origin rpy="0 0 0" xyz="0 0 -0.02325"/>
  </joint>
  <joint name="r_middle_mcp" type="revolute">
    <parent link="r_middle_flexion_one"/>
    <child link="r_middle_flexion_two"/>
    <origin rpy="0 0 0" xyz="0 0 0"/>
    <axis xyz="-1 0 0"/>
    <limit effort="100" lower="-2" upper="100" velocity="1000"/>
  </joint>
  <joint name="r_middle_tip" type="revolute">
    <parent link="r_middle_flexion_two"/>
    <child link="r_middle_flexion_three"/>
    <origin rpy="0 0 0" xyz="0 0 -0.0876"/>
    <axis xyz="-1 0 0"/>
    <limit effort="100" lower="0" upper="100" velocity="1000"/>
  </joint>
  <joint name="r_hub_to_ring_brake" type="fixed">
    <parent link="r_glove_hub"/>
    <child link="r_ring_brake"/>
    <origin rpy="0 0 0" xyz="0.011 0.008 -0.05422"/>
  </joint>
  <joint name="r_ring_brake" type="revolute">
    <parent link="r_ring_brake"/>
    <child link="r_ring_abduction"/>
    <origin rpy="0 0 0" xyz="0 0.0074 -0.0"/>
    <axis xyz="0 1 0"/>
    <limit effort="100" lower="-2" upper="100" velocity="1000"/>
  </joint>
  <joint name="r_ring_abduction" type="fixed">
    <parent link="r_ring_abduction"/>
    <child link="r_ring_flexion_one"/>
    <origin rpy="0 0 0" xyz="0 0 -0.02325"/>
  </joint>
  <joint name="r_ring_mcp" type="revolute">
    <parent link="r_ring_flexion_one"/>
    <child link="r_ring_flexion_two"/>
    <origin rpy="0 0 0" xyz="0 0 0"/>
    <axis xyz="-1 0 0"/>
    <limit effort="100" lower="-2" upper="100" velocity="1000"/>
  </joint>
  <joint name="r_ring_tip" type="revolute">
    <parent link="r_ring_flexion_two"/>
    <child link="r_ring_flexion_three"/>
    <origin rpy="0 0 0" xyz="0 0 -0.0876"/>
    <axis xyz="-1 0 0"/>
    <limit effort="100" lower="0" upper="100" velocity="1000"/>
  </joint>
  <joint name="r_hub_to_pinky_brake" type="fixed">
    <parent link="r_glove_hub"/>
    <child link="r_pinky_brake"/>
    <origin rpy="0 0 0" xyz="0.03307 0.00695 -0.04125"/>
  </joint>
  <joint name="r_pinky_brake" type="revolute">
    <parent link="r_pinky_brake"/>
    <child link="r_pinky_abduction"/>
    <origin rpy="0 0 0" xyz="0 0.0074 -0.0"/>
    <axis xyz="0 1 0"/>
    <limit effort="100" lower="-2" upper="100" velocity="1000"/>
  </joint>
  <joint name="r_pinky_abduction" type="fixed">
    <parent link="r_pinky_abduction"/>
    <child link="r_pinky_flexion_one"/>
    <origin rpy="0 0 0" xyz="0 0 -0.02325"/>
  </joint>
  <joint name="r_pinky_mcp" type="revolute">
    <parent link="r_pinky_flexion_one"/>
    <child link="r_pinky_flexion_two"/>
    <origin rpy="0 0 0" xyz="0 0 0"/>
    <axis xyz="-1 0 0"/>
    <limit effort="100" lower="-2" upper="100" velocity="1000"/>
  </joint>
  <joint name="r_pinky_tip" type="revolute">
    <parent link="r_pinky_flexion_two"/>
    <child link="r_pinky_flexion_three"/>
    <origin rpy="0 0 0" xyz="0 0 -0.0876"/>
    <axis xyz="-1 0 0"/>
    <limit effort="100" lower="0" upper="100" velocity="1000"/>
  </joint>
</robot>
